2017-08-01 06:17:06.635478 Start.
Evaluating SKM detector on BirdVox-70k, unit03
with a temporal tolerance of 500 ms.
mir_eval version: 0.4
numpy version: 1.13.1
pandas version: 0.20.3

Traceback (most recent call last):
  File "/home/vl1019/miniconda3/lib/python3.6/site-packages/pandas/core/indexes/base.py", line 2442, in get_loc
    return self._engine.get_loc(key)
  File "pandas/_libs/index.pyx", line 132, in pandas._libs.index.IndexEngine.get_loc (pandas/_libs/index.c:5280)
  File "pandas/_libs/index.pyx", line 154, in pandas._libs.index.IndexEngine.get_loc (pandas/_libs/index.c:5126)
  File "pandas/_libs/hashtable_class_helper.pxi", line 1210, in pandas._libs.hashtable.PyObjectHashTable.get_item (pandas/_libs/hashtable.c:20523)
  File "pandas/_libs/hashtable_class_helper.pxi", line 1218, in pandas._libs.hashtable.PyObjectHashTable.get_item (pandas/_libs/hashtable.c:20477)
KeyError: 'Calls'

During handling of the above exception, another exception occurred:

Traceback (most recent call last):
  File "../src/007_evaluate-skm.py", line 73, in <module>
    relevant_rows = annotation.loc[~annotation["Calls"].isin(negative_labels)]
  File "/home/vl1019/miniconda3/lib/python3.6/site-packages/pandas/core/frame.py", line 1964, in __getitem__
    return self._getitem_column(key)
  File "/home/vl1019/miniconda3/lib/python3.6/site-packages/pandas/core/frame.py", line 1971, in _getitem_column
    return self._get_item_cache(key)
  File "/home/vl1019/miniconda3/lib/python3.6/site-packages/pandas/core/generic.py", line 1645, in _get_item_cache
    values = self._data.get(item)
  File "/home/vl1019/miniconda3/lib/python3.6/site-packages/pandas/core/internals.py", line 3590, in get
    loc = self.items.get_loc(item)
  File "/home/vl1019/miniconda3/lib/python3.6/site-packages/pandas/core/indexes/base.py", line 2444, in get_loc
    return self._engine.get_loc(self._maybe_cast_indexer(key))
  File "pandas/_libs/index.pyx", line 132, in pandas._libs.index.IndexEngine.get_loc (pandas/_libs/index.c:5280)
  File "pandas/_libs/index.pyx", line 154, in pandas._libs.index.IndexEngine.get_loc (pandas/_libs/index.c:5126)
  File "pandas/_libs/hashtable_class_helper.pxi", line 1210, in pandas._libs.hashtable.PyObjectHashTable.get_item (pandas/_libs/hashtable.c:20523)
  File "pandas/_libs/hashtable_class_helper.pxi", line 1218, in pandas._libs.hashtable.PyObjectHashTable.get_item (pandas/_libs/hashtable.c:20477)
KeyError: 'Calls'
